<?xml version="1.0"?>
<sdf version="1.6">

  <model name="f1_renault_ackermann_harmonic_laser">
    <pose>0 0 0.0 0 0 0</pose>

    <link name='base_link'>
      <inertial>
        <mass>0.1</mass>
        <inertia>
          <ixx>0.001</ixx>
          <ixy>0</ixy>
          <ixz>0</ixz>
          <iyy>0.001</iyy>
          <iyz>0</iyz>
          <izz>0.001</izz>
        </inertia>
      </inertial>
    </link>

    <joint name='chassis_link_joint' type='fixed'>
      <pose>0.0 0.0 0.0 0 0 0</pose>
      <parent>base_link</parent>
      <child>chassis_link</child>
    </joint>

    <link name='chassis_link'>
      <inertial>
        <pose>0.0000002 0.014614 0.130192 0 -0 0</pose>
        <mass>1580</mass>
        <inertia>
          <ixx>1997.86</ixx>
          <ixy>-3e-05</ixy>
          <ixz>-1e-06</ixz>
          <iyy>442.769</iyy>
          <iyz>62.5206</iyz>
          <izz>2238.05</izz>
        </inertia>
      </inertial>
      <collision name='chassis_link_fixed_joint_lump__chassis_link_collision'>
        <pose>0 0.302 0 0 -0 1.5708</pose>
        <geometry>
          <mesh>
            <scale>1.0 1.0 1.0</scale>
            <uri>model://f1_renault_camera/Renault/chasis.dae</uri>
          </mesh>
        </geometry>
        <surface>
          <contact>
            <ode />
          </contact>
          <friction>
            <ode>
              <mu>0.2</mu>
              <mu2>0.2</mu2>
            </ode>
          </friction>
        </surface>
      </collision>
      <visual name='chassis_link_fixed_joint_lump__chassis_link_visual'>
        <!-- <pose>0 1.51 0 0 -0 1.5708</pose> -->
        <pose>0 0.302 0 1.5708 -0 1.5708</pose>
        <geometry>
          <mesh>
            <scale>1.0 1.0 1.0</scale>
            <uri>model://f1_renault_camera/Renault/chasis.obj</uri>
          </mesh>
        </geometry>
      </visual>
      <self_collide>0</self_collide>
    </link>

    <!-- Back Left Wheel -->
    <joint name='bl_axle' type='revolute'>
      <pose relative_to='chassis_link'>-0.155 -0.366728 0.0649994 0 -0 0</pose>
      <parent>chassis_link</parent>
      <child>bl_1</child>
      <axis>
        <xyz>-1 0 0</xyz>
        <limit>
          <effort>1000</effort>
          <velocity>100</velocity>
        </limit>
        <dynamics>
          <friction>12.031606150200002</friction>
        </dynamics>
      </axis>
    </joint>
    <link name='bl_1'>
      <pose relative_to='bl_axle'>0 0 0 0 -0 0</pose>
      <inertial>
        <pose>-0.0377 0 -0 0 -0 0</pose>
        <mass>24.5</mass>
        <inertia>
          <ixx>1.84514</ixx>
          <ixy>0</ixy>
          <ixz>0</ixz>
          <iyy>1.04961</iyy>
          <iyz>0</iyz>
          <izz>1.04961</izz>
        </inertia>
      </inertial>
      <collision name='bl_1_collision'>
        <pose>0.175 0.20252 0.028 0 -0 0</pose>
        <geometry>
          <mesh>
            <scale>0.0002 0.0002 0.0002</scale>
            <uri>model://f1_renault_camera/Renault/bl_1.stl</uri>
          </mesh>
        </geometry>
        <surface>
          <contact>
            <ode />
          </contact>
          <friction>
            <ode>
              <mu>1.7</mu>
              <mu2>1.7</mu2>
            </ode>
          </friction>
        </surface>
      </collision>
      <visual name='bl_1_visual'>
        <!-- <pose>0.875 1.0136 0.1444 0 -0 0</pose> -->
        <pose>0.175 0.028 -0.20252 0 -0 0</pose>
        <geometry>
          <mesh>
            <scale>0.02 0.02 0.02</scale>
            <uri>model://f1_renault_camera/Renault/back_left.obj</uri>
          </mesh>
        </geometry>
      </visual>
      <self_collide>0</self_collide>
    </link>

    <!-- Back Right Wheel -->
    <joint name='br_axle' type='revolute'>
      <pose relative_to='chassis_link'>0.155 -0.366728 0.0649994 0 -0 0</pose>
      <parent>chassis_link</parent>
      <child>br_1</child>
      <axis>
        <xyz>-1 0 0</xyz>
        <limit>
          <effort>1000</effort>
          <velocity>100</velocity>
        </limit>
        <dynamics>
          <friction>12.031606150200002</friction>
        </dynamics>
      </axis>
    </joint>
    <link name='br_1'>
      <pose relative_to='br_axle'>0 0 0 0 -0 0</pose>
      <inertial>
        <pose>-0.0377 0 -0 0 -0 0</pose>
        <mass>24.5</mass>
        <inertia>
          <ixx>1.84514</ixx>
          <ixy>0</ixy>
          <ixz>0</ixz>
          <iyy>1.04961</iyy>
          <iyz>0</iyz>
          <izz>1.04961</izz>
        </inertia>
      </inertial>
      <collision name='br_1_collision'>
        <pose>-0.175 0.20252 0.028 0 0 0</pose>
        <geometry>
          <mesh>
            <scale>0.0002 0.0002 0.0002</scale>
            <uri>model://f1_renault_camera/Renault/br_1.stl</uri>
          </mesh>
        </geometry>
        <surface>
          <contact>
            <ode />
          </contact>
          <friction>
            <ode>
              <mu>1.7</mu>
              <mu2>1.7</mu2>
            </ode>
          </friction>
        </surface>
      </collision>
      <visual name='br_1_visual'>
        <!-- <pose>-0.875 1.0136 0.1444 0 -0 0</pose> -->
        <pose>-0.175 0.028 -0.20252 0 -0 0</pose>
        <geometry>
          <mesh>
            <scale>0.02 0.02 0.02</scale>
            <uri>model://f1_renault_camera/Renault/back_right.obj</uri>
          </mesh>
        </geometry>
      </visual>
      <self_collide>0</self_collide>
    </link> 


    <!-- Steering Wheel -->
    <joint name="steering_joint" type="revolute">
      <pose relative_to='chassis_link'>-0.002 0.12 0.12 0 0 0</pose>
      <parent>chassis_link</parent>
      <child>steering_wheel</child>
      <axis>
        <xyz>0.0 -1.0 0.0</xyz>
        <limit>
          <lower>-5</lower>
          <upper>5</upper>
          <effort>100</effort>
          <velocity>10</velocity>
        </limit>
        <dynamics>
          <damping>10.0</damping>
        </dynamics>
        <use_parent_model_frame>true</use_parent_model_frame>
      </axis>
      <physics>
        <ode>
          <cfm_damping>1</cfm_damping>
        </ode>
      </physics>
    </joint>
    <link name='steering_wheel'>
      <pose relative_to='steering_joint'>0 0.174 -0.108 0 0 1.5708</pose>
      <inertial>
        <mass>0.5</mass>
        <inertia>
          <ixx>0.01</ixx>
          <ixy>0</ixy>
          <ixz>0</ixz>
          <iyy>0.01</iyy>
          <iyz>0</iyz>
          <izz>0.01</izz>
        </inertia>
      </inertial>
      <visual name='steering_wheel_visual'>
        <pose>0 0 0 0 0 0</pose>
        <geometry>
          <mesh>
            <scale>0.94 0.94 0.94</scale>
            <uri>model://f1_renault_camera/Renault/steering_wheel.dae</uri>
          </mesh>
        </geometry>
      </visual>
      <self_collide>1</self_collide>
    </link>

    
    <!-- Left Steering -->
    <!-- <joint name='l_steer' type='revolute'>
      <pose relative_to='chassis_link'>-0.825 1.51736 0.324997 0 -0 0</pose>
      <parent>chassis_link</parent>
      <child>l_steer_1</child>
      <axis>
        <xyz>0 0 1</xyz>
        <limit>
          <lower>-0.95</lower>
          <upper>0.95</upper>
        </limit>
        <dynamics>
          <friction>18.0474092253</friction>
        </dynamics>
      </axis>
    </joint>
    <link name='l_steer_1'>
      <pose relative_to='l_steer'>0 0 0 0 -0 0</pose>
      <inertial>
        <pose>0.003381 0 0.02162 0 -0 0</pose>
        <mass>1</mass>
        <inertia>
          <ixx>1</ixx>
          <ixy>0</ixy>
          <ixz>0</ixz>
          <iyy>1</iyy>
          <iyz>0</iyz>
          <izz>1</izz>
        </inertia>
      </inertial>
      <self_collide>0</self_collide>
    </link> -->

    <!-- Single Steering Joint for both front wheels -->
    <joint name='front_steering' type='revolute'>
      <pose relative_to='chassis_link'>0 0.303472 0.0649994 0 -0 0</pose>
      <parent>chassis_link</parent>
      <child>front_steering_link</child>
      <axis>
        <xyz>0 0 1</xyz>
        <limit>
          <lower>-0.3</lower>
          <upper>0.3</upper>
          <effort>1000</effort>
          <velocity>2</velocity>
        </limit>
        <dynamics>
          <friction>0.5</friction>
          <damping>0.1</damping>
        </dynamics>
      </axis>
    </joint>
    <link name='front_steering_link'>
      <pose relative_to='front_steering'>0 0 0 0 -0 0</pose>
      <inertial>
        <pose>0 0 0 0 -0 0</pose>
        <mass>2</mass>
        <inertia>
          <ixx>0.01</ixx>
          <ixy>0</ixy>
          <ixz>0</ixz>
          <iyy>0.01</iyy>
          <iyz>0</iyz>
          <izz>0.01</izz>
        </inertia>
      </inertial>
      <self_collide>0</self_collide>
    </link>

    <!-- Front Left Wheel -->
    <joint name='fl_axle' type='revolute'>
      <pose relative_to='front_steering_link'>-0.165 0 0 0 -0 0</pose>
      <parent>front_steering_link</parent>
      <child>fl_1</child>
      <axis>
        <xyz>-1 0 0</xyz>
        <limit>
          <effort>1000</effort>
          <velocity>100</velocity>
        </limit>
        <dynamics>
          <friction>12.031606150200002</friction>
        </dynamics>
      </axis>
    </joint>
    <link name='fl_1'>
      <pose relative_to='fl_axle'>0 0 0 0 -0 0</pose>
      <inertial>
        <pose>-0.0377 0 -0 0 -0 0</pose>
        <mass>24.5</mass>
        <inertia>
          <ixx>1.84514</ixx>
          <ixy>0</ixy>
          <ixz>0</ixz>
          <iyy>1.04961</iyy>
          <iyz>0</iyz>
          <izz>1.04961</izz>
        </inertia>
      </inertial>
      <collision name='fl_1_collision'>
        <pose>0.175 -0.30348 0.02888 0 -0 0</pose>
        <geometry>
          <mesh>
            <scale>0.0002 0.0002 0.0002</scale>
            <uri>model://f1_renault_camera/Renault/fl_1.stl</uri>
          </mesh>
        </geometry>
        <surface>
          <contact>
            <ode />
          </contact>
          <friction>
            <ode>
              <mu>1.1</mu>
              <mu2>1.1</mu2>
            </ode>
          </friction>
        </surface>
      </collision>
      <visual name='fl_1_visual'>
        <!-- <pose>0.875 -1.5174 0.1444 0 -0 0</pose> -->
        <pose>0.175 0.02888 0.30348 0 -0 0</pose>
        <geometry>
          <mesh>
            <scale>0.02 0.02 0.02</scale>
            <uri>model://f1_renault_camera/Renault/front_left.obj</uri>
          </mesh>
        </geometry>
      </visual>
      <self_collide>0</self_collide>
    </link>
    
    <!-- Right Steering -->
    <!-- <joint name='r_steer' type='revolute'>
      <pose relative_to='chassis_link'>0.825 1.51736 0.324997 0 -0 0</pose>
      <parent>chassis_link</parent>
      <child>r_steer_1</child>
      <axis>
        <xyz>0 0 1</xyz>
        <limit>
          <lower>-0.95</lower>
          <upper>0.95</upper>
        </limit>
        <dynamics>
          <damping>0.01</damping>
          <friction>18.0474092253</friction>
        </dynamics>
      </axis>
    </joint>
    <link name='r_steer_1'>
      <pose relative_to='r_steer'>0 0 0 0 -0 0</pose>
      <inertial>
        <pose>0.003381 0 0.02162 0 -0 0</pose>
        <mass>1</mass>
        <inertia>
          <ixx>1</ixx>
          <ixy>0</ixy>
          <ixz>0</ixz>
          <iyy>1</iyy>
          <iyz>0</iyz>
          <izz>1</izz>
        </inertia>
      </inertial>
      <self_collide>0</self_collide>
    </link> -->

    <!-- Front Right Wheel -->
    <joint name='fr_axle' type='revolute'>
      <pose relative_to='front_steering_link'>0.165 0 0 0 -0 0</pose>
      <parent>front_steering_link</parent>
      <child>fr_1</child>
      <axis>
        <xyz>-1 0 0</xyz>
        <limit>
          <effort>1000</effort>
          <velocity>100</velocity>
        </limit>
        <dynamics>
          <friction>12.031606150200002</friction>
        </dynamics>
      </axis>
    </joint>
    <link name='fr_1'>
      <pose relative_to='fr_axle'>0 0 0 0 -0 0</pose>
      <inertial>
        <pose>-0.00754 0 -0 0 -0 0</pose>
        <mass>24.5</mass>
        <inertia>
          <ixx>1.84514</ixx>
          <ixy>0</ixy>
          <ixz>0</ixz>
          <iyy>1.04961</iyy>
          <iyz>0</iyz>
          <izz>1.04961</izz>
        </inertia>
      </inertial>
      <collision name='fr_1_collision'>
        <pose>-0.175 -0.30348 0.02888 0 -0 0</pose>
        <geometry>
          <mesh>
            <scale>0.0002 0.0002 0.0002</scale>
            <uri>model://f1_renault_camera/Renault/fr_1.stl</uri>
          </mesh>
        </geometry>
        <surface>
          <contact>
            <ode />
          </contact>
          <friction>
            <ode>
              <mu>1.7</mu>
              <mu2>1.7</mu2>
            </ode>
          </friction>
        </surface>
      </collision>
      <visual name='fr_1_visual'>
        <!-- <pose>-0.875 -1.5174 0.1444 0 -0 0</pose> -->
        <pose>-0.175 0.02888 0.30348 0 -0 0</pose>
        <geometry>
          <mesh>
            <scale>0.02 0.02 0.02</scale>
            <uri>model://f1_renault_camera/Renault/front_right.obj</uri>
          </mesh>
        </geometry>
      </visual>
    </link>
    
    <link name="camera_link"/>

    <link name="camera_rgb_frame">
      <inertial>
        <pose>0.0138 -0.0094 0.0214 0 0 0</pose>
        <inertia>
          <ixx>0.001</ixx>
          <ixy>0.000</ixy>
          <ixz>0.000</ixz>
          <iyy>0.001</iyy>
          <iyz>0.000</iyz>
          <izz>0.001</izz>
        </inertia>
        <mass>0.035</mass>
      </inertial>

      <!-- OLD POSE -->
      <!-- <pose>0.0138 -0.0094 0.0214 0 0 0</pose> -->

      <!-- NEW POSE -->
      <pose>0 2.7 0.2 0 0 1.57</pose>

      <sensor name="camera" type="camera">
        <always_on>true</always_on>
        <visualize>true</visualize>
        <update_rate>30</update_rate>
        <topic>/cam_f1_left/image_raw</topic>
        <gz_frame_id>camera_rgb_frame</gz_frame_id>
        <camera name="intel_realsense_r200">
          <camera_info_topic>/cam_f1_left/camera_info</camera_info_topic>
          <horizontal_fov>1.02974</horizontal_fov>
          <image>
            <width>1920</width>
            <height>1080</height>
            <format>R8G8B8</format>
          </image>
          <clip>
            <near>0.02</near>
            <far>300</far>
          </clip>
          <noise>
            <type>gaussian</type>
            <!-- Noise is sampled independently per pixel on each frame.
                  That pixel's noise value is added to each of its color
                  channels, which at that point lie in the range [0,1]. -->
            <mean>0.0</mean>
            <stddev>0.007</stddev>
          </noise>
        </camera> 
      </sensor>
    </link>

    <joint name="camera_joint" type="fixed">
      <parent>chassis_link</parent>
      <child>camera_link</child>
      <pose>0.0128 -0.013 0.0188 0 0 0</pose>
      <axis>
        <xyz>0 0 1</xyz>
      </axis>
    </joint>

    <joint name="camera_rgb_joint" type="fixed">
      <parent>camera_link</parent>
      <child>camera_rgb_frame</child>
      <pose>0.001 0.0036 0.0026 0 0 0</pose>
      <axis>
        <xyz>0 0 1</xyz>
      </axis>
    </joint>

    <!-- Gazebo Harmonic Plugins -->
    
    <!-- Ackermann Steering Plugin -->
    <plugin filename="gz-sim-ackermann-steering-system" name="gz::sim::systems::AckermannSteering">
      <left_joint>fl_axle</left_joint>
      <left_joint>bl_axle</left_joint>
      <right_joint>fr_axle</right_joint>
      <right_joint>br_axle</right_joint>
      <left_steering_joint>front_steering</left_steering_joint>
      <right_steering_joint>front_steering</right_steering_joint>
      <kingpin_width>1.65</kingpin_width>
      <steering_limit>0.3</steering_limit>
      <wheel_base>3.351</wheel_base>
      <wheel_separation>1.65</wheel_separation>
      <wheel_radius>0.3425</wheel_radius>
      <sub_topic>steer_angle</sub_topic>
      <min_velocity>-50</min_velocity>
      <max_velocity>50</max_velocity>
      <min_acceleration>-50</min_acceleration>
      <max_acceleration>50</max_acceleration>
      <topic>/F1ROS/cmd_vel</topic>
    </plugin>

    <!-- Velocity Control Plugin for rear wheels -->
    <!-- <plugin filename="gz-sim-velocity-control-system" name="gz::sim::systems::VelocityControl">
      <joint_name>bl_axle</joint_name>
      <joint_name>br_axle</joint_name>
      <sub_topic>/model/f1_renault_ackermann_harmonic_laser/cmd_vel</sub_topic>
      <use_actuator_msg>true</use_actuator_msg>
      <actuator_number>0</actuator_number>
      <actuator_number>1</actuator_number>
    </plugin> -->

    <!-- Joint State Publisher -->
    <plugin filename="gz-sim-joint-state-publisher-system" name="gz::sim::systems::JointStatePublisher">
      <joint_name>fl_axle</joint_name>
      <joint_name>fr_axle</joint_name>
      <joint_name>bl_axle</joint_name>
      <joint_name>br_axle</joint_name>
      <joint_name>front_steering</joint_name>
      <joint_name>steering_joint</joint_name>
    </plugin>

    <!-- Odometry Publisher -->
    <plugin filename="gz-sim-odometry-publisher-system" name="gz::sim::systems::OdometryPublisher">
      <odom_topic>F1ROS/odom</odom_topic>
      <robot_base_frame>chassis_link</robot_base_frame>
      <odom_frame>odom</odom_frame>
      <odom_publish_frequency>50</odom_publish_frequency>
      <dimensions>3</dimensions>
    </plugin>

    <!-- Pose Publisher -->
    <plugin filename="gz-sim-pose-publisher-system" name="gz::sim::systems::PosePublisher">
      <publish_link_pose>true</publish_link_pose>
      <publish_collision_pose>false</publish_collision_pose>
      <publish_visual_pose>false</publish_visual_pose>
      <publish_nested_model_pose>true</publish_nested_model_pose>
      <update_frequency>50</update_frequency>
    </plugin>

    <!-- Joint Position Controller for steering wheel (optional) -->
    <plugin filename="gz-sim-joint-position-controller-system" name="gz::sim::systems::JointPositionController">
      <joint_name>steering_joint</joint_name>
      <sub_topic>steering_wheel_cmd</sub_topic>
      <p_gain>10</p_gain>
      <i_gain>0.1</i_gain>
      <d_gain>1</d_gain>
    </plugin>

  </model>

</sdf>